{"results": {"test_pep8.Test": {"passes": {"test_pep8.Test.test_pep8": ""}}, "test_a1.TestA1": {"errors": {"test_a1.TestA1.test_add_matrix_defaults": {"message": "'NoneType' object has no attribute 'get_val'", "description": "", "details": "Traceback (most recent call last):\n\n  File \"/usr/local/cms/python-3.4.2/lib/python3.4/unittest/case.py\", line 58, in testPartExecutor\n    yield\n\n  File \"/usr/local/cms/python-3.4.2/lib/python3.4/unittest/case.py\", line 577, in run\n    testMethod()\n\n  File \"/home/a08test/submissions/adhika21/a1p2/test_a1.py\", line 371, in test_add_matrix_defaults\n    self.assertEqual(r.get_val(1, 1), 3, \"adding 2 matrices not producing correct default values\")\n\nAttributeError: 'NoneType' object has no attribute 'get_val'\n"}, "test_a1.TestA1.test_get_col_values": {"message": "'NoneType' object has no attribute 'get_item'", "description": "", "details": "Traceback (most recent call last):\n\n  File \"/usr/local/cms/python-3.4.2/lib/python3.4/unittest/case.py\", line 58, in testPartExecutor\n    yield\n\n  File \"/usr/local/cms/python-3.4.2/lib/python3.4/unittest/case.py\", line 577, in run\n    testMethod()\n\n  File \"/home/a08test/submissions/adhika21/a1p2/test_a1.py\", line 269, in test_get_col_values\n    self.assertEqual(r.get_item(2), 9, \"col retrieved didn't have value put into original matrix\")\n\nAttributeError: 'NoneType' object has no attribute 'get_item'\n"}, "test_a1.TestA1.test_matrix_mult": {"message": "'Matrix' object has no attribute '_row_giver'", "description": "", "details": "Traceback (most recent call last):\n\n  File \"/usr/local/cms/python-3.4.2/lib/python3.4/unittest/case.py\", line 58, in testPartExecutor\n    yield\n\n  File \"/usr/local/cms/python-3.4.2/lib/python3.4/unittest/case.py\", line 577, in run\n    testMethod()\n\n  File \"/home/a08test/submissions/adhika21/a1p2/test_a1.py\", line 437, in test_matrix_mult\n    r = m1.multiply_matrix(m2)\n\n  File \"/home/a08test/submissions/adhika21/a1p2/a1.py\", line 360, in multiply_matrix\n    if self.col_giver() != mult_matrix._row_giver():\n\nAttributeError: 'Matrix' object has no attribute '_row_giver'\n"}, "test_a1.TestA1.test_add_matrix_set_nodes": {"message": "'NoneType' object has no attribute 'get_val'", "description": "", "details": "Traceback (most recent call last):\n\n  File \"/usr/local/cms/python-3.4.2/lib/python3.4/unittest/case.py\", line 58, in testPartExecutor\n    yield\n\n  File \"/usr/local/cms/python-3.4.2/lib/python3.4/unittest/case.py\", line 577, in run\n    testMethod()\n\n  File \"/home/a08test/submissions/adhika21/a1p2/test_a1.py\", line 401, in test_add_matrix_set_nodes\n    self.assertEqual(r.get_val(1, 1), 3, \"adding 2 matrices not producing correct matrix\")\n\nAttributeError: 'NoneType' object has no attribute 'get_val'\n"}, "test_a1.TestA1.test_get_col_1d": {"message": "'NoneType' object has no attribute 'get_item'", "description": "", "details": "Traceback (most recent call last):\n\n  File \"/usr/local/cms/python-3.4.2/lib/python3.4/unittest/case.py\", line 58, in testPartExecutor\n    yield\n\n  File \"/usr/local/cms/python-3.4.2/lib/python3.4/unittest/case.py\", line 577, in run\n    testMethod()\n\n  File \"/home/a08test/submissions/adhika21/a1p2/test_a1.py\", line 243, in test_get_col_1d\n    self.assertEqual(c.get_item(1), 9, \"get_col reslt accessed as a OneDimensionalMatrix not returning correct values\")\n\nAttributeError: 'NoneType' object has no attribute 'get_item'\n"}, "test_a1.TestA1.test_get_row_values": {"message": "'NoneType' object has no attribute 'get_item'", "description": "", "details": "Traceback (most recent call last):\n\n  File \"/usr/local/cms/python-3.4.2/lib/python3.4/unittest/case.py\", line 58, in testPartExecutor\n    yield\n\n  File \"/usr/local/cms/python-3.4.2/lib/python3.4/unittest/case.py\", line 577, in run\n    testMethod()\n\n  File \"/home/a08test/submissions/adhika21/a1p2/test_a1.py\", line 257, in test_get_row_values\n    self.assertEqual(r.get_item(2), 9, \"row retrieved didn't have value put into original matrix\")\n\nAttributeError: 'NoneType' object has no attribute 'get_item'\n"}, "test_a1.TestA1.test_matrix_mult_dimensions": {"message": "'Matrix' object has no attribute '_row_giver'", "description": "", "details": "Traceback (most recent call last):\n\n  File \"/usr/local/cms/python-3.4.2/lib/python3.4/unittest/case.py\", line 58, in testPartExecutor\n    yield\n\n  File \"/usr/local/cms/python-3.4.2/lib/python3.4/unittest/case.py\", line 577, in run\n    testMethod()\n\n  File \"/home/a08test/submissions/adhika21/a1p2/test_a1.py\", line 457, in test_matrix_mult_dimensions\n    r = m1.multiply_matrix(m2)\n\n  File \"/home/a08test/submissions/adhika21/a1p2/a1.py\", line 360, in multiply_matrix\n    if self.col_giver() != mult_matrix._row_giver():\n\nAttributeError: 'Matrix' object has no attribute '_row_giver'\n"}, "test_a1.TestA1.test_diagonal_invalid": {"message": "__init__() missing 1 required positional argument: 'n'", "description": "", "details": "Traceback (most recent call last):\n\n  File \"/usr/local/cms/python-3.4.2/lib/python3.4/unittest/case.py\", line 58, in testPartExecutor\n    yield\n\n  File \"/usr/local/cms/python-3.4.2/lib/python3.4/unittest/case.py\", line 577, in run\n    testMethod()\n\n  File \"/home/a08test/submissions/adhika21/a1p2/test_a1.py\", line 525, in test_diagonal_invalid\n    m = a1.DiagonalMatrix(3)\n\nTypeError: __init__() missing 1 required positional argument: 'n'\n"}, "test_a1.TestA1.test_identity_invalid_2": {"message": "__init__() missing 1 required positional argument: 'n'", "description": "", "details": "Traceback (most recent call last):\n\n  File \"/usr/local/cms/python-3.4.2/lib/python3.4/unittest/case.py\", line 58, in testPartExecutor\n    yield\n\n  File \"/usr/local/cms/python-3.4.2/lib/python3.4/unittest/case.py\", line 577, in run\n    testMethod()\n\n  File \"/home/a08test/submissions/adhika21/a1p2/test_a1.py\", line 557, in test_identity_invalid_2\n    m = a1.IdentityMatrix(3)\n\nTypeError: __init__() missing 1 required positional argument: 'n'\n"}, "test_a1.TestA1.test_add_matrix_dimensions": {"message": "", "description": "", "details": "Traceback (most recent call last):\n\n  File \"/usr/local/cms/python-3.4.2/lib/python3.4/unittest/case.py\", line 58, in testPartExecutor\n    yield\n\n  File \"/usr/local/cms/python-3.4.2/lib/python3.4/unittest/case.py\", line 577, in run\n    testMethod()\n\n  File \"/home/a08test/submissions/adhika21/a1p2/test_a1.py\", line 413, in test_add_matrix_dimensions\n    r = m1.add_matrix(m2)\n\n  File \"/home/a08test/submissions/adhika21/a1p2/a1.py\", line 354, in add_matrix\n    raise MatrixInvalidOperationError()\n\na1.MatrixInvalidOperationError\n"}, "test_a1.TestA1.test_identity_invalid": {"message": "__init__() missing 1 required positional argument: 'n'", "description": "", "details": "Traceback (most recent call last):\n\n  File \"/usr/local/cms/python-3.4.2/lib/python3.4/unittest/case.py\", line 58, in testPartExecutor\n    yield\n\n  File \"/usr/local/cms/python-3.4.2/lib/python3.4/unittest/case.py\", line 577, in run\n    testMethod()\n\n  File \"/home/a08test/submissions/adhika21/a1p2/test_a1.py\", line 547, in test_identity_invalid\n    m = a1.IdentityMatrix(3)\n\nTypeError: __init__() missing 1 required positional argument: 'n'\n"}, "test_a1.TestA1.test_set_val_nodes_3": {"message": "'Matrix' object has no attribute '_node_creaotr'", "description": "", "details": "Traceback (most recent call last):\n\n  File \"/usr/local/cms/python-3.4.2/lib/python3.4/unittest/case.py\", line 58, in testPartExecutor\n    yield\n\n  File \"/usr/local/cms/python-3.4.2/lib/python3.4/unittest/case.py\", line 577, in run\n    testMethod()\n\n  File \"/home/a08test/submissions/adhika21/a1p2/test_a1.py\", line 118, in test_set_val_nodes_3\n    m.set_val(1, 1, 11)\n\n  File \"/home/a08test/submissions/adhika21/a1p2/a1.py\", line 278, in set_val\n    self._hold_row = self._indexer(\"row\", self._ind_y)\n\n  File \"/home/a08test/submissions/adhika21/a1p2/a1.py\", line 220, in _indexer\n    self._helper.set_down(self._node_creaotr(\n\nAttributeError: 'Matrix' object has no attribute '_node_creaotr'\n"}, "test_a1.TestA1.test_transpose": {"message": "__init__() missing 1 required positional argument: 'n'", "description": "", "details": "Traceback (most recent call last):\n\n  File \"/usr/local/cms/python-3.4.2/lib/python3.4/unittest/case.py\", line 58, in testPartExecutor\n    yield\n\n  File \"/usr/local/cms/python-3.4.2/lib/python3.4/unittest/case.py\", line 577, in run\n    testMethod()\n\n  File \"/home/a08test/submissions/adhika21/a1p2/test_a1.py\", line 467, in test_transpose\n    m1 = a1.SquareMatrix(3)\n\nTypeError: __init__() missing 1 required positional argument: 'n'\n"}, "test_a1.TestA1.test_diagonal": {"message": "__init__() missing 1 required positional argument: 'n'", "description": "", "details": "Traceback (most recent call last):\n\n  File \"/usr/local/cms/python-3.4.2/lib/python3.4/unittest/case.py\", line 58, in testPartExecutor\n    yield\n\n  File \"/usr/local/cms/python-3.4.2/lib/python3.4/unittest/case.py\", line 577, in run\n    testMethod()\n\n  File \"/home/a08test/submissions/adhika21/a1p2/test_a1.py\", line 481, in test_diagonal\n    m1 = a1.SquareMatrix(3)\n\nTypeError: __init__() missing 1 required positional argument: 'n'\n"}, "test_a1.TestA1.test_get_val_index_error": {"message": "", "description": "", "details": "Traceback (most recent call last):\n\n  File \"/usr/local/cms/python-3.4.2/lib/python3.4/unittest/case.py\", line 58, in testPartExecutor\n    yield\n\n  File \"/usr/local/cms/python-3.4.2/lib/python3.4/unittest/case.py\", line 577, in run\n    testMethod()\n\n  File \"/home/a08test/submissions/adhika21/a1p2/test_a1.py\", line 77, in test_get_val_index_error\n    m.get_val(4, 4)\n\n  File \"/home/a08test/submissions/adhika21/a1p2/a1.py\", line 250, in get_val\n    raise MatrixDimensionError()\n\na1.MatrixDimensionError\n"}, "test_a1.TestA1.test_get_row_set_col": {"message": "_traversal() missing 1 required positional argument: 'index'", "description": "", "details": "Traceback (most recent call last):\n\n  File \"/usr/local/cms/python-3.4.2/lib/python3.4/unittest/case.py\", line 58, in testPartExecutor\n    yield\n\n  File \"/usr/local/cms/python-3.4.2/lib/python3.4/unittest/case.py\", line 577, in run\n    testMethod()\n\n  File \"/home/a08test/submissions/adhika21/a1p2/test_a1.py\", line 309, in test_get_row_set_col\n    m.set_col(1, r)\n\n  File \"/home/a08test/submissions/adhika21/a1p2/a1.py\", line 308, in set_col\n    self._index = self._traversal(\"col\", col_num)\n\nTypeError: _traversal() missing 1 required positional argument: 'index'\n"}, "test_a1.TestA1.test_symmetric_matrix": {"message": "__init__() missing 1 required positional argument: 'n'", "description": "", "details": "Traceback (most recent call last):\n\n  File \"/usr/local/cms/python-3.4.2/lib/python3.4/unittest/case.py\", line 58, in testPartExecutor\n    yield\n\n  File \"/usr/local/cms/python-3.4.2/lib/python3.4/unittest/case.py\", line 577, in run\n    testMethod()\n\n  File \"/home/a08test/submissions/adhika21/a1p2/test_a1.py\", line 499, in test_symmetric_matrix\n    m1 = a1.SymmetricMatrix(3)\n\nTypeError: __init__() missing 1 required positional argument: 'n'\n"}, "test_a1.TestA1.test_identity": {"message": "__init__() missing 1 required positional argument: 'n'", "description": "", "details": "Traceback (most recent call last):\n\n  File \"/usr/local/cms/python-3.4.2/lib/python3.4/unittest/case.py\", line 58, in testPartExecutor\n    yield\n\n  File \"/usr/local/cms/python-3.4.2/lib/python3.4/unittest/case.py\", line 577, in run\n    testMethod()\n\n  File \"/home/a08test/submissions/adhika21/a1p2/test_a1.py\", line 535, in test_identity\n    m = a1.IdentityMatrix(3)\n\nTypeError: __init__() missing 1 required positional argument: 'n'\n"}, "test_a1.TestA1.test_set_val_index_error": {"message": "", "description": "", "details": "Traceback (most recent call last):\n\n  File \"/usr/local/cms/python-3.4.2/lib/python3.4/unittest/case.py\", line 58, in testPartExecutor\n    yield\n\n  File \"/usr/local/cms/python-3.4.2/lib/python3.4/unittest/case.py\", line 577, in run\n    testMethod()\n\n  File \"/home/a08test/submissions/adhika21/a1p2/test_a1.py\", line 189, in test_set_val_index_error\n    m.set_val(5, 5, 9)\n\n  File \"/home/a08test/submissions/adhika21/a1p2/a1.py\", line 270, in set_val\n    raise MatrixDimensionError()\n\na1.MatrixDimensionError\n"}, "test_a1.TestA1.test_diagonal_matrix": {"message": "__init__() missing 1 required positional argument: 'n'", "description": "", "details": "Traceback (most recent call last):\n\n  File \"/usr/local/cms/python-3.4.2/lib/python3.4/unittest/case.py\", line 58, in testPartExecutor\n    yield\n\n  File \"/usr/local/cms/python-3.4.2/lib/python3.4/unittest/case.py\", line 577, in run\n    testMethod()\n\n  File \"/home/a08test/submissions/adhika21/a1p2/test_a1.py\", line 511, in test_diagonal_matrix\n    m1 = a1.DiagonalMatrix(3)\n\nTypeError: __init__() missing 1 required positional argument: 'n'\n"}, "test_a1.TestA1.test_get_set_row": {"message": "_traversal() missing 1 required positional argument: 'index'", "description": "", "details": "Traceback (most recent call last):\n\n  File \"/usr/local/cms/python-3.4.2/lib/python3.4/unittest/case.py\", line 58, in testPartExecutor\n    yield\n\n  File \"/usr/local/cms/python-3.4.2/lib/python3.4/unittest/case.py\", line 577, in run\n    testMethod()\n\n  File \"/home/a08test/submissions/adhika21/a1p2/test_a1.py\", line 295, in test_get_set_row\n    m.set_col(2, r)\n\n  File \"/home/a08test/submissions/adhika21/a1p2/a1.py\", line 308, in set_col\n    self._index = self._traversal(\"col\", col_num)\n\nTypeError: _traversal() missing 1 required positional argument: 'index'\n"}}, "passes": {"test_a1.TestA1.test_add_matrix_defaults_unchanged": "", "test_a1.TestA1.test_set_val_nodes_6": "", "test_a1.TestA1.test_set_val_nodes_1": "", "test_a1.TestA1.test_add_scalar_default_2": "", "test_a1.TestA1.test_set_val_nodes_5": "", "test_a1.TestA1.test_set_val_nodes_8": "", "test_a1.TestA1.test_init": "", "test_a1.TestA1.test_get_val": "", "test_a1.TestA1.test_set_val_nodes_4": "", "test_a1.TestA1.test_add_scalar_default": "", "test_a1.TestA1.test_get_val_default": "", "test_a1.TestA1.test_set_val_nodes_2": "", "test_a1.TestA1.test_set_val_nodes_7": ""}, "failures": {"test_a1.TestA1.test_add_scalar_2": {"message": "<a1.MatrixNode object at 0x7ff1a9b3cd68> != 18 : scalar addition not working on set node", "description": "", "details": "Traceback (most recent call last):\n\n  File \"/usr/local/cms/python-3.4.2/lib/python3.4/unittest/case.py\", line 58, in testPartExecutor\n    yield\n\n  File \"/usr/local/cms/python-3.4.2/lib/python3.4/unittest/case.py\", line 577, in run\n    testMethod()\n\n  File \"/home/a08test/submissions/adhika21/a1p2/test_a1.py\", line 335, in test_add_scalar_2\n    self.assertEqual(m.get_val(1, 2), 18, \"scalar addition not working on set node\")\n\n  File \"/usr/local/cms/python-3.4.2/lib/python3.4/unittest/case.py\", line 797, in assertEqual\n    assertion_func(first, second, msg=msg)\n\n  File \"/usr/local/cms/python-3.4.2/lib/python3.4/unittest/case.py\", line 790, in _baseAssertEqual\n    raise self.failureException(msg)\n\nAssertionError: <a1.MatrixNode object at 0x7ff1a9b3cd68> != 18 : scalar addition not working on set node\n"}, "test_a1.TestA1.test_set_val": {"message": "<a1.MatrixNode object at 0x7ff1a9b678d0> != 9 : get_val not setting value correctly", "description": "", "details": "Traceback (most recent call last):\n\n  File \"/usr/local/cms/python-3.4.2/lib/python3.4/unittest/case.py\", line 58, in testPartExecutor\n    yield\n\n  File \"/usr/local/cms/python-3.4.2/lib/python3.4/unittest/case.py\", line 577, in run\n    testMethod()\n\n  File \"/home/a08test/submissions/adhika21/a1p2/test_a1.py\", line 89, in test_set_val\n    self.assertEqual(m.get_val(1, 1), 9, \"get_val not setting value correctly\")\n\n  File \"/usr/local/cms/python-3.4.2/lib/python3.4/unittest/case.py\", line 797, in assertEqual\n    assertion_func(first, second, msg=msg)\n\n  File \"/usr/local/cms/python-3.4.2/lib/python3.4/unittest/case.py\", line 790, in _baseAssertEqual\n    raise self.failureException(msg)\n\nAssertionError: <a1.MatrixNode object at 0x7ff1a9b678d0> != 9 : get_val not setting value correctly\n"}, "test_a1.TestA1.test_get_col_type": {"message": "False is not true : get_col not returning a OneDimensionalMatrix", "description": "", "details": "Traceback (most recent call last):\n\n  File \"/usr/local/cms/python-3.4.2/lib/python3.4/unittest/case.py\", line 58, in testPartExecutor\n    yield\n\n  File \"/usr/local/cms/python-3.4.2/lib/python3.4/unittest/case.py\", line 577, in run\n    testMethod()\n\n  File \"/home/a08test/submissions/adhika21/a1p2/test_a1.py\", line 231, in test_get_col_type\n    self.assertTrue(isinstance(m.get_col(1), a1.OneDimensionalMatrix), \"get_col not returning a OneDimensionalMatrix\")\n\n  File \"/usr/local/cms/python-3.4.2/lib/python3.4/unittest/case.py\", line 654, in assertTrue\n    raise self.failureException(msg)\n\nAssertionError: False is not true : get_col not returning a OneDimensionalMatrix\n"}, "test_a1.TestA1.test_set_val_deleting_nodes": {"message": "<a1.MatrixNode object at 0x7ff1a9b67f28> != None : setting a node back to default value not deleting the node", "description": "", "details": "Traceback (most recent call last):\n\n  File \"/usr/local/cms/python-3.4.2/lib/python3.4/unittest/case.py\", line 58, in testPartExecutor\n    yield\n\n  File \"/usr/local/cms/python-3.4.2/lib/python3.4/unittest/case.py\", line 577, in run\n    testMethod()\n\n  File \"/home/a08test/submissions/adhika21/a1p2/test_a1.py\", line 201, in test_set_val_deleting_nodes\n    self.assertEqual(m._head._right, None, \"setting a node back to default value not deleting the node\")\n\n  File \"/usr/local/cms/python-3.4.2/lib/python3.4/unittest/case.py\", line 797, in assertEqual\n    assertion_func(first, second, msg=msg)\n\n  File \"/usr/local/cms/python-3.4.2/lib/python3.4/unittest/case.py\", line 790, in _baseAssertEqual\n    raise self.failureException(msg)\n\nAssertionError: <a1.MatrixNode object at 0x7ff1a9b67f28> != None : setting a node back to default value not deleting the node\n"}, "test_a1.TestA1.test_add_scalar": {"message": "0 != 9 : scalar addition not working on non-set node", "description": "", "details": "Traceback (most recent call last):\n\n  File \"/usr/local/cms/python-3.4.2/lib/python3.4/unittest/case.py\", line 58, in testPartExecutor\n    yield\n\n  File \"/usr/local/cms/python-3.4.2/lib/python3.4/unittest/case.py\", line 577, in run\n    testMethod()\n\n  File \"/home/a08test/submissions/adhika21/a1p2/test_a1.py\", line 323, in test_add_scalar\n    self.assertEqual(m.get_val(1, 1), 9, \"scalar addition not working on non-set node\")\n\n  File \"/usr/local/cms/python-3.4.2/lib/python3.4/unittest/case.py\", line 797, in assertEqual\n    assertion_func(first, second, msg=msg)\n\n  File \"/usr/local/cms/python-3.4.2/lib/python3.4/unittest/case.py\", line 790, in _baseAssertEqual\n    raise self.failureException(msg)\n\nAssertionError: 0 != 9 : scalar addition not working on non-set node\n"}, "test_a1.TestA1.test_set_val_default_nodes_2": {"message": "<a1.MatrixNode object at 0x7ff1a9b67d30> != None : setting a cell to the default value should not create a new node", "description": "", "details": "Traceback (most recent call last):\n\n  File \"/usr/local/cms/python-3.4.2/lib/python3.4/unittest/case.py\", line 58, in testPartExecutor\n    yield\n\n  File \"/usr/local/cms/python-3.4.2/lib/python3.4/unittest/case.py\", line 577, in run\n    testMethod()\n\n  File \"/home/a08test/submissions/adhika21/a1p2/test_a1.py\", line 177, in test_set_val_default_nodes_2\n    self.assertEqual(m._head._right, None, \"setting a cell to the default value should not create a new node\")\n\n  File \"/usr/local/cms/python-3.4.2/lib/python3.4/unittest/case.py\", line 797, in assertEqual\n    assertion_func(first, second, msg=msg)\n\n  File \"/usr/local/cms/python-3.4.2/lib/python3.4/unittest/case.py\", line 790, in _baseAssertEqual\n    raise self.failureException(msg)\n\nAssertionError: <a1.MatrixNode object at 0x7ff1a9b67d30> != None : setting a cell to the default value should not create a new node\n"}, "test_a1.TestA1.test_set_val_default_nodes": {"message": "<a1.MatrixNode object at 0x7ff1a9b67b38> != None : setting a cell to the default value should not create a new node", "description": "", "details": "Traceback (most recent call last):\n\n  File \"/usr/local/cms/python-3.4.2/lib/python3.4/unittest/case.py\", line 58, in testPartExecutor\n    yield\n\n  File \"/usr/local/cms/python-3.4.2/lib/python3.4/unittest/case.py\", line 577, in run\n    testMethod()\n\n  File \"/home/a08test/submissions/adhika21/a1p2/test_a1.py\", line 165, in test_set_val_default_nodes\n    self.assertEqual(m._head._right, None, \"setting a cell to the default value should not create a new node\")\n\n  File \"/usr/local/cms/python-3.4.2/lib/python3.4/unittest/case.py\", line 797, in assertEqual\n    assertion_func(first, second, msg=msg)\n\n  File \"/usr/local/cms/python-3.4.2/lib/python3.4/unittest/case.py\", line 790, in _baseAssertEqual\n    raise self.failureException(msg)\n\nAssertionError: <a1.MatrixNode object at 0x7ff1a9b67b38> != None : setting a cell to the default value should not create a new node\n"}, "test_a1.TestA1.test_set_val_deleting_nodes_2": {"message": "<a1.MatrixNode object at 0x7ff1a9b72160> != None : setting a node back to default value not deleting the node", "description": "", "details": "Traceback (most recent call last):\n\n  File \"/usr/local/cms/python-3.4.2/lib/python3.4/unittest/case.py\", line 58, in testPartExecutor\n    yield\n\n  File \"/usr/local/cms/python-3.4.2/lib/python3.4/unittest/case.py\", line 577, in run\n    testMethod()\n\n  File \"/home/a08test/submissions/adhika21/a1p2/test_a1.py\", line 213, in test_set_val_deleting_nodes_2\n    self.assertEqual(m._head._right, None, \"setting a node back to default value not deleting the node\")\n\n  File \"/usr/local/cms/python-3.4.2/lib/python3.4/unittest/case.py\", line 797, in assertEqual\n    assertion_func(first, second, msg=msg)\n\n  File \"/usr/local/cms/python-3.4.2/lib/python3.4/unittest/case.py\", line 790, in _baseAssertEqual\n    raise self.failureException(msg)\n\nAssertionError: <a1.MatrixNode object at 0x7ff1a9b72160> != None : setting a node back to default value not deleting the node\n"}, "test_a1.TestA1.test_get_row_type": {"message": "False is not true : get_row not returning a OneDimensionalMatrix", "description": "", "details": "Traceback (most recent call last):\n\n  File \"/usr/local/cms/python-3.4.2/lib/python3.4/unittest/case.py\", line 58, in testPartExecutor\n    yield\n\n  File \"/usr/local/cms/python-3.4.2/lib/python3.4/unittest/case.py\", line 577, in run\n    testMethod()\n\n  File \"/home/a08test/submissions/adhika21/a1p2/test_a1.py\", line 223, in test_get_row_type\n    self.assertTrue(isinstance(m.get_row(1), a1.OneDimensionalMatrix), \"get_row not returning a OneDimensionalMatrix\")\n\n  File \"/usr/local/cms/python-3.4.2/lib/python3.4/unittest/case.py\", line 654, in assertTrue\n    raise self.failureException(msg)\n\nAssertionError: False is not true : get_row not returning a OneDimensionalMatrix\n"}}}}, "origin": "/home/a08test/submissions/adhika21/a1p2", "students": [{"student_id": "adhika21", "email": "rishav.adhikari@mail.utoronto.ca", "last": "Adhikari", "source": "N/A", "first": "Rishav", "student_number": "0000000000", "section": "N/A"}], "assignment": "a1p2", "date": "2016-03-12T23:59:30"}